Workbook
Name PriorityList: Setup!$B$2:$B$5
Name RequestTypeList: Setup!$C$2:$C$17
Name StaffList: Setup!$D$2:$D$5
Name StatusList: Setup!$A$2:$A$5

Sheet Dashboard
B2: IT SERVICE TICKETS DASHBOARD
B5: KEY PERFORMANCE INDICATORS
B7: Total Tickets | D7: Open Tickets | F7: Closed/Resolved | H7: Critical Open
B8: =COUNTA('IT Service Tickets'!B:B)-1 | D8: =COUNTIF('IT Service Tickets'!C:C,"In Progress")+COUNTIF('IT Service Tickets'!C:C,"Waiting for Info") | F8: =COUNTIF('IT Service Tickets'!C:C,"Closed")+COUNTIF('IT Service Tickets'!C:C,"Resolved") | H8: =COUNTIFS('IT Service Tickets'!D:D,"Critical",'IT Service Tickets'!C:C,"<>Closed",'IT Service Tickets'!C:C,"<>Resolved")
B10: Resolution Rate | D10: High Priority Open | F10: Waiting for Info | H10: This Week
B11: =IF(COUNTA('IT Service Tickets'!B:B)-1=0,"-",TEXT((COUNTIF('IT Service Tickets'!C:C,"Closed")+COUNTIF('IT Service Tickets'!C:C,"Resolved"))/(COUNTA('IT Service Tickets'!B:B)-1),"0%")) | D11: =COUNTIFS('IT Service Tickets'!D:D,"High",'IT Service Tickets'!C:C,"<>Closed",'IT Service Tickets'!C:C,"<>Resolved") | F11: =COUNTIF('IT Service Tickets'!C:C,"Waiting for Info") | H11: =COUNTIFS('IT Service Tickets'!H:H,">="&(Setup!$G$2-7),'IT Service Tickets'!H:H,"<="&Setup!$G$2)
B14: STATUS BREAKDOWN | F14: PRIORITY BREAKDOWN
B16: Status | C16: Count | D16: % | F16: Priority | G16: Count | H16: %
B17: Closed | C17: =COUNTIF('IT Service Tickets'!C:C,"Closed") | D17: =IF($B$8=0,"-",C17/$B$8) | F17: Critical | G17: =COUNTIF('IT Service Tickets'!D:D,"Critical") | H17: =IF($B$8=0,"-",G17/$B$8)
B18: Resolved | C18: =COUNTIF('IT Service Tickets'!C:C,"Resolved") | D18: =IF($B$8=0,"-",C18/$B$8) | F18: High | G18: =COUNTIF('IT Service Tickets'!D:D,"High") | H18: =IF($B$8=0,"-",G18/$B$8)
B19: In Progress | C19: =COUNTIF('IT Service Tickets'!C:C,"In Progress") | D19: =IF($B$8=0,"-",C19/$B$8) | F19: Medium | G19: =COUNTIF('IT Service Tickets'!D:D,"Medium") | H19: =IF($B$8=0,"-",G19/$B$8)
B20: Waiting for Info | C20: =COUNTIF('IT Service Tickets'!C:C,"Waiting for Info") | D20: =IF($B$8=0,"-",C20/$B$8) | F20: Low | G20: =COUNTIF('IT Service Tickets'!D:D,"Low") | H20: =IF($B$8=0,"-",G20/$B$8)
B23: REQUEST TYPES | F23: STAFF WORKLOAD
B25: Request Type | C25: Total | D25: Open | F25: Staff | G25: Assigned | H25: Open
B26: Account Changes | C26: =COUNTIF('IT Service Tickets'!E:E,"Account Changes") | D26: =COUNTIFS('IT Service Tickets'!E:E,"Account Changes",'IT Service Tickets'!C:C,"<>Closed",'IT Service Tickets'!C:C,"<>Resolved") | F26: Angel Pinzon | G26: =COUNTIF('IT Service Tickets'!F:F,"*Angel Pinzon*") | H26: =COUNTIFS('IT Service Tickets'!F:F,"*Angel Pinzon*",'IT Service Tickets'!C:C,"<>Closed",'IT Service Tickets'!C:C,"<>Resolved")
B27: Account Setup | C27: =COUNTIF('IT Service Tickets'!E:E,"Account Setup") | D27: =COUNTIFS('IT Service Tickets'!E:E,"Account Setup",'IT Service Tickets'!C:C,"<>Closed",'IT Service Tickets'!C:C,"<>Resolved") | F27: VC3 | G27: =COUNTIF('IT Service Tickets'!F:F,"*VC3*") | H27: =COUNTIFS('IT Service Tickets'!F:F,"*VC3*",'IT Service Tickets'!C:C,"<>Closed",'IT Service Tickets'!C:C,"<>Resolved")
B28: Company Website Issues | C28: =COUNTIF('IT Service Tickets'!E:E,"Company Website Issues") | D28: =COUNTIFS('IT Service Tickets'!E:E,"Company Website Issues",'IT Service Tickets'!C:C,"<>Closed",'IT Service Tickets'!C:C,"<>Resolved") | F28: Angel + VC3 | G28: =COUNTIF('IT Service Tickets'!F:F,"*@Angel Pinzon @VC3*") | H28: =COUNTIFS('IT Service Tickets'!F:F,"*@Angel Pinzon @VC3*",'IT Service Tickets'!C:C,"<>Closed",'IT Service Tickets'!C:C,"<>Resolved")
B29: Documentation Request | C29: =COUNTIF('IT Service Tickets'!E:E,"Documentation Request") | D29: =COUNTIFS('IT Service Tickets'!E:E,"Documentation Request",'IT Service Tickets'!C:C,"<>Closed",'IT Service Tickets'!C:C,"<>Resolved") | F29: Angel + Manuel | G29: =COUNTIF('IT Service Tickets'!F:F,"*@Angel Pinzon @Manuel*") | H29: =COUNTIFS('IT Service Tickets'!F:F,"*@Angel Pinzon @Manuel*",'IT Service Tickets'!C:C,"<>Closed",'IT Service Tickets'!C:C,"<>Resolved")
B30: Email Issues | C30: =COUNTIF('IT Service Tickets'!E:E,"Email Issues") | D30: =COUNTIFS('IT Service Tickets'!E:E,"Email Issues",'IT Service Tickets'!C:C,"<>Closed",'IT Service Tickets'!C:C,"<>Resolved")
B31: Feedback Request | C31: =COUNTIF('IT Service Tickets'!E:E,"Feedback Request") | D31: =COUNTIFS('IT Service Tickets'!E:E,"Feedback Request",'IT Service Tickets'!C:C,"<>Closed",'IT Service Tickets'!C:C,"<>Resolved")
B32: Hardware Adquisition | C32: =COUNTIF('IT Service Tickets'!E:E,"Hardware Adquisition") | D32: =COUNTIFS('IT Service Tickets'!E:E,"Hardware Adquisition",'IT Service Tickets'!C:C,"<>Closed",'IT Service Tickets'!C:C,"<>Resolved")
B33: Hardware Setup | C33: =COUNTIF('IT Service Tickets'!E:E,"Hardware Setup") | D33: =COUNTIFS('IT Service Tickets'!E:E,"Hardware Setup",'IT Service Tickets'!C:C,"<>Closed",'IT Service Tickets'!C:C,"<>Resolved")
B34: Network Problems | C34: =COUNTIF('IT Service Tickets'!E:E,"Network Problems") | D34: =COUNTIFS('IT Service Tickets'!E:E,"Network Problems",'IT Service Tickets'!C:C,"<>Closed",'IT Service Tickets'!C:C,"<>Resolved")
B35: Permission Changes | C35: =COUNTIF('IT Service Tickets'!E:E,"Permission Changes") | D35: =COUNTIFS('IT Service Tickets'!E:E,"Permission Changes",'IT Service Tickets'!C:C,"<>Closed",'IT Service Tickets'!C:C,"<>Resolved")
B36: Server Issues | C36: =COUNTIF('IT Service Tickets'!E:E,"Server Issues") | D36: =COUNTIFS('IT Service Tickets'!E:E,"Server Issues",'IT Service Tickets'!C:C,"<>Closed",'IT Service Tickets'!C:C,"<>Resolved")
B37: Software Acquisition | C37: =COUNTIF('IT Service Tickets'!E:E,"Software Acquisition") | D37: =COUNTIFS('IT Service Tickets'!E:E,"Software Acquisition",'IT Service Tickets'!C:C,"<>Closed",'IT Service Tickets'!C:C,"<>Resolved")
B38: Software Issues | C38: =COUNTIF('IT Service Tickets'!E:E,"Software Issues") | D38: =COUNTIFS('IT Service Tickets'!E:E,"Software Issues",'IT Service Tickets'!C:C,"<>Closed",'IT Service Tickets'!C:C,"<>Resolved")
B39: Software Setup | C39: =COUNTIF('IT Service Tickets'!E:E,"Software Setup") | D39: =COUNTIFS('IT Service Tickets'!E:E,"Software Setup",'IT Service Tickets'!C:C,"<>Closed",'IT Service Tickets'!C:C,"<>Resolved")
B40: Spam Removal | C40: =COUNTIF('IT Service Tickets'!E:E,"Spam Removal") | D40: =COUNTIFS('IT Service Tickets'!E:E,"Spam Removal",'IT Service Tickets'!C:C,"<>Closed",'IT Service Tickets'!C:C,"<>Resolved")
B41: System Access | C41: =COUNTIF('IT Service Tickets'!E:E,"System Access") | D41: =COUNTIFS('IT Service Tickets'!E:E,"System Access",'IT Service Tickets'!C:C,"<>Closed",'IT Service Tickets'!C:C,"<>Resolved")
B44: RECENT TICKETS (Last 5) | H44: COLOR LEGEND
B46: Ticket ID | C46: Title | D46: Status | E46: Priority | F46: Date | H46: Status
B47: =IFERROR(INDEX('IT Service Tickets'!A:A,COUNTA('IT Service Tickets'!B:B)-0),"") | C47: =IFERROR(INDEX('IT Service Tickets'!B:B,COUNTA('IT Service Tickets'!B:B)-0),"") | D47: =IFERROR(INDEX('IT Service Tickets'!C:C,COUNTA('IT Service Tickets'!B:B)-0),"") | E47: =IFERROR(INDEX('IT Service Tickets'!D:D,COUNTA('IT Service Tickets'!B:B)-0),"") | F47: =IFERROR(INDEX('IT Service Tickets'!H:H,COUNTA('IT Service Tickets'!B:B)-0),"") | H47: Closed
B48: =IFERROR(INDEX('IT Service Tickets'!A:A,COUNTA('IT Service Tickets'!B:B)-1),"") | C48: =IFERROR(INDEX('IT Service Tickets'!B:B,COUNTA('IT Service Tickets'!B:B)-1),"") | D48: =IFERROR(INDEX('IT Service Tickets'!C:C,COUNTA('IT Service Tickets'!B:B)-1),"") | E48: =IFERROR(INDEX('IT Service Tickets'!D:D,COUNTA('IT Service Tickets'!B:B)-1),"") | F48: =IFERROR(INDEX('IT Service Tickets'!H:H,COUNTA('IT Service Tickets'!B:B)-1),"") | H48: Resolved
B49: =IFERROR(INDEX('IT Service Tickets'!A:A,COUNTA('IT Service Tickets'!B:B)-2),"") | C49: =IFERROR(INDEX('IT Service Tickets'!B:B,COUNTA('IT Service Tickets'!B:B)-2),"") | D49: =IFERROR(INDEX('IT Service Tickets'!C:C,COUNTA('IT Service Tickets'!B:B)-2),"") | E49: =IFERROR(INDEX('IT Service Tickets'!D:D,COUNTA('IT Service Tickets'!B:B)-2),"") | F49: =IFERROR(INDEX('IT Service Tickets'!H:H,COUNTA('IT Service Tickets'!B:B)-2),"") | H49: In Progress
B50: =IFERROR(INDEX('IT Service Tickets'!A:A,COUNTA('IT Service Tickets'!B:B)-3),"") | C50: =IFERROR(INDEX('IT Service Tickets'!B:B,COUNTA('IT Service Tickets'!B:B)-3),"") | D50: =IFERROR(INDEX('IT Service Tickets'!C:C,COUNTA('IT Service Tickets'!B:B)-3),"") | E50: =IFERROR(INDEX('IT Service Tickets'!D:D,COUNTA('IT Service Tickets'!B:B)-3),"") | F50: =IFERROR(INDEX('IT Service Tickets'!H:H,COUNTA('IT Service Tickets'!B:B)-3),"") | H50: Waiting for Info
B51: =IFERROR(INDEX('IT Service Tickets'!A:A,COUNTA('IT Service Tickets'!B:B)-4),"") | C51: =IFERROR(INDEX('IT Service Tickets'!B:B,COUNTA('IT Service Tickets'!B:B)-4),"") | D51: =IFERROR(INDEX('IT Service Tickets'!C:C,COUNTA('IT Service Tickets'!B:B)-4),"") | E51: =IFERROR(INDEX('IT Service Tickets'!D:D,COUNTA('IT Service Tickets'!B:B)-4),"") | F51: =IFERROR(INDEX('IT Service Tickets'!H:H,COUNTA('IT Service Tickets'!B:B)-4),"")
H52: Priority
H53: Critical | J53: System-wide outages or issues affecting multiple users/locations simultaneously. Business operations are significantly impacted with no workaround available. (e.g., server down, ERP unavailable, major network outage)
H54: High | J54: Issues affecting key business functions or multiple users, but a workaround may exist. Needs resolution within 24-48 hours. (e.g., firewall issues, network problems at a location, critical hardware acquisition)
...

Sheet Setup
A1: Status Options | B1: Priority Options | C1: Request Types | D1: Staff Options | F1: Current Year | G1: Today
A2: Closed | B2: Critical | C2: Account Changes | D2: @Angel Pinzon | F2: 2025 | G2: =TODAY()
A3: Resolved | B3: High | C3: Account Setup | D3: @VC3
A4: In Progress | B4: Medium | C4: Company Website Issues | D4: @Angel Pinzon @VC3
A5: Waiting for Info | B5: Low | C5: Documentation Request | D5: @Angel Pinzon @Manuel Menchaca
C6: Email Issues
C7: Feedback Request
C8: Hardware Adquisition
C9: Hardware Setup
C10: Network Problems
C11: Permission Changes
C12: Server Issues
C13: Software Acquisition
C14: Software Issues
C15: Software Setup
C16: Spam Removal
C17: System Access

Sheet IT Service Tickets
A1: Ticket ID | B1: Ticket Title | C1: Status | D1: Priority | E1: Request Type | F1: Staff Assigned | G1: Requester | H1: Date | I1: Days Open | J1: Description | K1: Resolution Notes
A2: =IF(B2="","","IT-"&Setup!$F$2&TEXT(ROW()-1,"0000")) | B2: Issues with CA-ProductionLaptop | C2: Closed | D2: Medium | E2: Software Issues | F2: @Angel Pinzon | G2: Leonel Ramirez | H2: 45999 | I2: =IF(OR(H2="",B2=""),"",IF(OR(C2="Closed",C2="Resolved"),"-",Setup!$G$2-H2)) | J2: Leonel Informed production laptop was not working | K2: Issue related with the machine #6 and fixed by Julio, not the computer, now working properly.
A3: =IF(B3="","","IT-"&Setup!$F$2&TEXT(ROW()-1,"0000")) | B3: Risk Matrix of MSP Transition | C3: Closed | D3: Medium | E3: Documentation Request | F3: @Angel Pinzon | G3: Mariana Orozco | H3: 45996 | I3: =IF(OR(H3="",B3=""),"",IF(OR(C3="Closed",C3="Resolved"),"-",Setup!$G$2-H3)) | J3: Provide risk matrix documentation for MSP transition | K3: Documentation provided, waiting on feedback
A4: =IF(B4="","","IT-"&Setup!$F$2&TEXT(ROW()-1,"0000")) | B4: Adobe Acrobat Error | C4: Closed | D4: Low | E4: Software Issues | F4: @Angel Pinzon @VC3 | G4: Angelina Solis | H4: 45996 | I4: =IF(OR(H4="",B4=""),"",IF(OR(C4="Closed",C4="Resolved"),"-",Setup!$G$2-H4)) | J4: Adobe has been giving me problems today, off and on. Sometimes I can print, while other times it freezes & this message pops up (at a much later time). Can you please help? | K4: Waiting for more information
A5: =IF(B5="","","IT-"&Setup!$F$2&TEXT(ROW()-1,"0000")) | B5: PHP Update - Company Website | C5: Resolved | D5: Medium | E5: Company Website Issues | F5: @Angel Pinzon | G5: Manuel Menchaca | H5: 45996 | I5: =IF(OR(H5="",B5=""),"",IF(OR(C5="Closed",C5="Resolved"),"-",Setup!$G$2-H5)) | J5: Company Website PHP needed to be upgraded to avoid older version maintenance fee charge ($71/mo) | K5: Accessed GoDaddy cAdmin Panel, upgraded PHP to version 8.4 reenable plug-ins to host company website accordingly.
A6: =IF(B6="","","IT-"&Setup!$F$2&TEXT(ROW()-1,"0000")) | B6: Printer setup for GA Production Manager | C6: Closed | D6: Low | E6: Hardware Setup | F6: @Angel Pinzon | G6: Mario Carter | H6: 45995 | I6: =IF(OR(H6="",B6=""),"",IF(OR(C6="Closed",C6="Resolved"),"-",Setup!$G$2-H6)) | J6: Mario needs help to install his new printer in the server as well as his computer | K6: Had a call with Mario, show him how to get the printer installed, he was able to confirm it works
A7: =IF(B7="","","IT-"&Setup!$F$2&TEXT(ROW()-1,"0000")) | B7: WallnerExpac/Unable to sign into domain profile in wifi connection | SSID WE | Texas location | C7: Resolved | D7: High | E7: Network Problems | F7: @VC3 | G7: Paula Jenkins | H7: 45995 | I7: =IF(OR(H7="",B7=""),"",IF(OR(C7="Closed",C7="Resolved"),"-",Setup!$G$2-H7)) | J7: Firewall giving issues affecting VPN connectivity. | K7: Hi Team, I have wrapped up part of the issues seen. Windstream was (finally) able to resolve the TX side being stuck on the cellular backup, as well as the primary link in California being down. I have requested that a client relations manager from windstream review the case to see about issuing a credit for the delay in repairs on their end. I have another ticket open with them to address the wifi in TX reaching the domain controller and should have that resolved soon. Thanks! Blake Keeffe Senior Systems Engineer
A8: =IF(B8="","","IT-"&Setup!$F$2&TEXT(ROW()-1,"0000")) | B8: Epicor Deployment URI not available | C8: In Progress | D8: High | E8: Server Issues | F8: @VC3 | G8: Monica Lopez | H8: 45995 | I8: =IF(OR(H8="",B8=""),"",IF(OR(C8="Closed",C8="Resolved"),"-",Setup!$G$2-H8)) | J8: We are reaching out regarding a recurring issue with Epicor client deployments: "deployment URI is not available on that specific client." This error has occurred multiple times across our environment | K8: Hello Team,Thanks for forwarding the information you gave me on 11/24 about this.After further investigation the log on the host where Epicor is running had a power loss event meaning the UPS that powers it stopped getting power from the wall socket, causing the APC software to shut down the virtual servers involved w/ Epicor.
A9: =IF(B9="","","IT-"&Setup!$F$2&TEXT(ROW()-1,"0000")) | B9: Desktop UPS needed for switch | C9: Closed | D9: High | E9: Hardware Adquisition | F9: @Angel Pinzon | G9: VC3 | H9: 45994 | I9: =IF(OR(H9="",B9=""),"",IF(OR(C9="Closed",C9="Resolved"),"-",Setup!$G$2-H9)) | J9: Desktop UPS needed for switch in GA | K9: Quote Approved, waiting on hardware installation
A10: =IF(B10="","","IT-"&Setup!$F$2&TEXT(ROW()-1,"0000")) | B10: Watchguard Firewalls Renewal | C10: Closed | D10: High | E10: Software Acquisition | F10: @Angel Pinzon | G10: VC3 | H10: 45994 | I10: =IF(OR(H10="",B10=""),"",IF(OR(C10="Closed",C10="Resolved"),"-",Setup!$G$2-H10)) | J10: Firewall Renewal for all locations | K10: Quote Approved
A11: =IF(B11="","","IT-"&Setup!$F$2&TEXT(ROW()-1,"0000")) | B11: Request to Disable Account | C11: Resolved | D11: Low | E11: Account Changes | F11: @VC3 | G11: Paula Jenkins | H11: 45994 | I11: =IF(OR(H11="",B11=""),"",IF(OR(C11="Closed",C11="Resolved"),"-",Setup!$G$2-H11)) | J11: Request to disable Lisa Hayes account | K11: Was handled by VC3, account deactivated.
A12: =IF(B12="","","IT-"&Setup!$F$2&TEXT(ROW()-1,"0000")) | B12: E-Drawings Install Request | C12: Resolved | D12: Low | E12: Software Setup | F12: @Angel Pinzon @VC3 | G12: Cody Baer | H12: 45993 | I12: =IF(OR(H12="",B12=""),"",IF(OR(C12="Closed",C12="Resolved"),"-",Setup!$G$2-H12)) | J12: Cody requested E-drawings to be installed in his computer | K12: Ticket was opened and software was installed by VC3
A13: =IF(B13="","","IT-"&Setup!$F$2&TEXT(ROW()-1,"0000")) | B13: Spam Removal | C13: Closed | D13: Low | E13: Spam Removal | F13: @VC3 | G13: Paul Omness | H13: 45993 | I13: =IF(OR(H13="",B13=""),"",IF(OR(C13="Closed",C13="Resolved"),"-",Setup!$G$2-H13)) | J13: Paul asked help to get this spam blocked | K13: VC3 went ahead and got the email adress blocked
... A28: =IF(B28="","","IT-"&Setup!$F$2&TEXT(ROW()-1,"0000")) | B28: Wire Transfer Confirmation | C28: Resolved | D28: Low | E28: Spam Removal | F28: @Angel Pinzon | G28: Mariana Orozco | H28: 45999 | I28: =IF(OR(H28="",B28=""),"",IF(OR(C28="Closed",C28="Resolved"),"-",Setup!$G$2-H28)) | J28: Mariana requested to block an spam email | K28: Open ticket with VC3, and they blocked the account.
A29: =IF(B29="","","IT-"&Setup!$F$2&TEXT(ROW()-1,"0000")) | B29: Install Epicor Test & Live in CA-UpConfrm2021 | C29: Closed | D29: Low | E29: Software Setup | F29: @Angel Pinzon @VC3 | G29: Monica Lopez | H29: 46001.31 | J29: Monica requested to install Epicor Test & Live in CA-UpConfrm2021 for handhelds testing
A30: =IF(B30="","","IT-"&Setup!$F$2&TEXT(ROW()-1,"0000")) | B30: Ticket#4737241 | User Termination | climas@expac.com | C30: Closed | D30: Low | E30: Account Changes | F30: @Angel Pinzon @VC3 | G30: Delia Flores | H30: 46003.26 | J30: Good Afternoon, We need help to terminate climas@expac.com , we will need to forward her emails to@Delia Flores | K30: I have revoked Cruz's sessions and reset her password as well as gave Delia full delegation to Cruz's mailbox. It should show up in her outlook automatically, she may need to close or re-open outlook to see it.
A31: =IF(B31="","","IT-"&Setup!$F$2&TEXT(ROW()-1,"0000")) | B31: Ticket#4736914 | User Termination | Mramos@expac.com | 2:00 PM MST | C31: Resolved | D31: Low | E31: Account Changes | F31: @Angel Pinzon @VC3 | G31: Leonel Ramirez | H31: 46003.261 | I31: =IF(OR(H31="",B31=""),"",IF(OR(C31="Closed",C31="Resolved"),"-",Setup!$G$2-H31)) | J31: Good Afternoon, We need help to terminate Mramos@expac.com at 2:00 PM MST, we will need to forward his emails to@Arturo Melendez And we need to change Mramos@expac.com password to !!decterm2025!! | K31: I've disabled Miguel's account and forwarded emails to Arturo.
A32: =IF(B32="","","IT-"&Setup!$F$2&TEXT(ROW()-1,"0000")) | B32: Ticket#4740840/WallnerExpac/Unable to login to VPN | C32: Resolved | D32: Low | E32: Network Problems | F32: @VC3 | G32: Taylor Huegel | H32: 46006.346 | I32: =IF(OR(H32="",B32=""),"",IF(OR(C32="Closed",C32="Resolved"),"-",Setup!$G$2-H32)) | J32: Taylor called, she is having issues trying to login to her VPN She is working from home, connected to the laptop with permission When trying to login, it loads for a bit before bringing her back to the login screen. She needs the VPN reinstalled. ca-prodsaleslptp
A33: =IF(B33="","","IT-"&Setup!$F$2&TEXT(ROW()-1,"0000")) | B33: PRTG-02 Alert: WallnerGA-ISP-SW01 - Ping (Ping) | C33: Waiting for Info | D33: Medium | E33: Server Issues | F33: @VC3 | G33: VC3 | H33: 46006.347 | I33: =IF(OR(H33="",B33=""),"",IF(OR(C33="Closed",C33="Resolved"),"-",Setup!$G$2-H33)) | J33: We've lost contact with one of the HP switch the HP-SW01-WEGA. It will be necessary to power cycle it to get it back online.
A34: =IF(B34="","","IT-"&Setup!$F$2&TEXT(ROW()-1,"0000")) | B34: Ticket#4746064/WallnerExpac/Software install spare laptop - CA-Travel1 | C34: Resolved | D34: Low | E34: Software Setup | F34: @VC3 | G34: VC3 | H34: 46007.417 | I34: =IF(OR(H34="",B34=""),"",IF(OR(C34="Closed",C34="Resolved"),"-",Setup!$G$2-H34)) | J34: Good Morning, Can we get some help to install these software to all users in the computer CA-TRAVEL1: Epicor Kinetic 2023.2 Test environment and Live enviroment RDS VPN We are using this computer as a device to check in/out for people that working for home Erika Requested the Computer. | K34: Hi Angel, I've installed the VPN and setup an RDS for the server. The VPN will automatically be available to everyone who logs in. I've moved the RDS as well as a .txt document with the VPN server address to the Public Desktop folder. That should make it so that it shows on the desktop of any user who logs into the computer. Now all that needs to be done is test them. Please give them a try and let me know if you run into any issues. Device name(s): CA-Travel1 Actions performed: Reviewing Speaking with Jason May not need to install Epicor client Rather just get an RDS going and both Test and Live are on the server Server for RDS is WEIRDS01 Contacting Angel via phone After speaking with Angel, I'm going to install the VPN and get an RDP setup for the server Will need to figure out how to get RDP onto all desktops Remoting into user's computer with their permission via VSA Computer is in the middle of installing Windows Updates Downloaded installer for Watchguard Mobile Installed Watchguard Created txt file with Server info and labeled it VPN Server Moved it to the Desktop of the Public user profile txt file now appears on all Desktops Setting up RDS
A35: =IF(B35="","","IT-"&Setup!$F$2&TEXT(ROW()-1,"0000")) | B35: Laptop for Slideshow Christmas Party | C35: Closed | D35: Low | E35: Hardware Setup | F35: @Angel Pinzon | G35: Manuel Menhanca | H35: 46007.419 | I35: =IF(OR(H35="",B35=""),"",IF(OR(C35="Closed",C35="Resolved"),"-",Setup!$G$2-H35)) | J35: Manny needed a laptop for Slideshow Christmas Party | K35: I asked him what requirements or software he needed, confirmed he had everything he needs, handed him the laptop.
A36: =IF(B36="","","IT-"&Setup!$F$2&TEXT(ROW()-1,"0000")) | B36: Ticket#4753166/WallnerExpac/Fw: TX Tool Room and Assembly - Epicor reporting | C36: Closed | D36: Low | E36: Software Setup | F36: @Angel Pinzon @VC3 | G36: Monica Lopez | H36: 46008.644 | I36: =IF(OR(H36="",B36=""),"",IF(OR(C36="Closed",C36="Resolved"),"-",Setup!$G$2-H36)) | J36: Setup RDP to RDS for Kinetic live and test | K36: Device name(s): TX-Toolroom2024 Actions performed: Reviewed with team Should just be setting up RDP to RDS Reviewed ITG Texas location uses RDP toc onnect to WEIRDS01 Remaining steps: setup RDP to WEIRDS01 Called and left VM
A37: =IF(B37="","","IT-"&Setup!$F$2&TEXT(ROW()-1,"0000")) | B37: TiTicket#4753051/WallnerExpac/GA-ProdMgr | mcarter@expac.com | C37: Closed | D37: Low | E37: Software Setup | F37: @Angel Pinzon @VC3 | G37: Monica Lopez | H37: 46008.646 | I37: =IF(OR(H37="",B37=""),"",IF(OR(C37="Closed",C37="Resolved"),"-",Setup!$G$2-H37)) | J37: Setup RDP to RDS | K37: Hi Angel, I tried giving Mario a call at 770-331-0644. Is there a better time or callback number for him? I also do not have an email address for Mario. Please respond to this email or give us a call at 800-481-4369, option 1, at your earliest convenience. You can also have Mario call us and reference ticket #4753051.
A38: =IF(B38="","","IT-"&Setup!$F$2&TEXT(ROW()-1,"0000")) | B38: Jermaine Franklin - (jfranklin@expac.com) disable account | C38: Closed | D38: Low | E38: Account Changes | F38: @Angel Pinzon @VC3 | G38: Angel Pinzon | H38: 46009.368 | I38: =IF(OR(H38="",B38=""),"",IF(OR(C38="Closed",C38="Resolved"),"-",Setup!$G$2-H38)) | J38: Good Morning, Please fully disable Jermaine Franklin - (jfranklin@expac.com) Best Regards,
A39: =IF(B39="","","IT-"&Setup!$F$2&TEXT(ROW()-1,"0000")) | B39: Lisa Hayes - LHayes@expac.com - Disable Account | C39: Closed | D39: Low | E39: Account Changes | F39: @Angel Pinzon @VC3 | G39: Angel Pinzon | H39: 46009.368 | I39: =IF(OR(H39="",B39=""),"",IF(OR(C39="Closed",C39="Resolved"),"-",Setup!$G$2-H39)) | J39: Good Morning, Please fully disable Lisa Hayes - LHayes@expac.com Best Regards,
A40: =IF(B40="","","IT-"&Setup!$F$2&TEXT(ROW()-1,"0000")) | B40: JBejar@expac.com password reset | C40: Closed | D40: Low | E40: Account Changes | F40: @Angel Pinzon @VC3 | G40: Angel Pinzon | H40: 46009.368 | I40: =IF(OR(H40="",B40=""),"",IF(OR(C40="Closed",C40="Resolved"),"-",Setup!$G$2-H40)) | J40: Good Morning, Can we please get the password for JBejar@expac.com reset, thanks. Best Regards,
A41: =IF(B41="","","IT-"&Setup!$F$2&TEXT(ROW()-1,"0000")) | B41: TX - Kiosk 2 & 3 locked out | C41: Closed | D41: Medium | E41: Hardware Setup | F41: @Angel Pinzon @VC3 | G41: Angel Pinzon | H41: 46009.369 | I41: =IF(OR(H41="",B41=""),"",IF(OR(C41="Closed",C41="Resolved"),"-",Setup!$G$2-H41)) | J41: Good Morning Kiosk 2 (tx-kiosk2-2025) & 3(tx-kiosk3) are locked out in TX, can we get help to unlock them, thanks. Contact: Lead Jose de la Fuente (915) 873-9256. Best Regards, | K41: Good morning It was a pleasure speaking with you today and I'm happy I could get you logged into both Kiosk computers. Per our conversation I have created a new ticket for the Zebra Printer issue - Service Ticket #4756090 - Epicor / Zebra Printer issue. I will send this ticket to you shortly.
A42: =IF(B42="","","IT-"&Setup!$F$2&TEXT(ROW()-1,"0000")) | B42: Ticket#4756090/WallnerExpac/Epicor / Zebra Printer issue | C42: Resolved | D42: Medium | E42: Hardware Setup | F42: @Angel Pinzon @VC3 | G42: Angel Pinzon | H42: 46009.39 | I42: =IF(OR(H42="",B42=""),"",IF(OR(C42="Closed",C42="Resolved"),"-",Setup!$G$2-H42)) | J42: Hi Jose, Good morning This email serves as the ticket for the Zebra printer issue we discussed earlier today. After our conversation, I consulted with the Dedicated Support Team, and they provided the following troubleshooting steps to help resolve the problem: Power Down the Printer: Please disconnect the printer from its power source. Re-thread the Labels: Carefully re-thread the labels, ensuring proper alignment. Restore Power and Test: Plug the printer back in and perform a test print. The team noted that these printers are highly sensitive to alignment issues, so ensuring the labels are properly threaded is critical. Once you have completed these steps, please let me know the results so we can determine the next course of action if needed. If you encounter any difficulties or have questions during the process, feel free to reach out to me directly. Thank you, Jeremy Meister Service Technician II | K42: Hi Jose, Thanks again for your time! My supervisor's recommendation was spot on - no Zebra label printers should be installed for Epicor printing, as Epicor has an internal printer assignment mechanism. We also confirmed the labels were no longer printing upside down. I appreciate your patience, and will update our documentation to reflect this info for a smoother future experience!
A43: =IF(B43="","","IT-"&Setup!$F$2&TEXT(ROW()-1,"0000")) | B43: Ticket#4756222/WallnerExpac/block email | C43: Closed | D43: Low | E43: Email Issues | F43: @Angel Pinzon @VC3 | G43: Angel Pinzon | H43: 46009.417 | I43: =IF(OR(H43="",B43=""),"",IF(OR(C43="Closed",C43="Resolved"),"-",Setup!$G$2-H43)) | J43: Good Morning, Please have this email blocked, thanks. (Please see below) Best Regards, | K43: Hi, Your issue with adding spam to the block list has been processed. Thank you for contacting VC3. Thank you, Nick Chiapparine Service Technician I
A44: =IF(B44="","","IT-"&Setup!$F$2&TEXT(ROW()-1,"0000")) | B44: User Count for DEC not matching | C44: In Progress | D44: Low | E44: Account Changes | F44: @VC3 @Jason Barnes | G44: Angel Pinzon | H44: 46013.343 | I44: =IF(OR(H44="",B44=""),"",IF(OR(C44="Closed",C44="Resolved"),"-",Setup!$G$2-H44)) | J44: Jason Barnes 12/18/2025 3:33 PM Hello All, I have verified these users are all disabled and unlicensed I am going to have the team look into why the user count is still showing them so it can be corrected. Thank you Jason B
A45: =IF(B45="","","IT-"&Setup!$F$2&TEXT(ROW()-1,"0000")) | B45: Ticket#4705557/WallnerExpac/Software installation request - CBaer@expac.com | C45: In Progress | D45: Low | E45: Permission Changes | F45: @Angel Pinzon @VC3 | G45: Cody Baer | H45: 46027.326 | I45: =IF(OR(H45="",B45=""),"",IF(OR(C45="Closed",C45="Resolved"),"-",Setup!$G$2-H45)) | J45: Good morning, This user is still awaiting the completion of his request: He needs to get Read and Write access to the following folder path: N:\12 Production\Georgia Production\Production Control User Contact Information: Computer Name: ga-runmngr-2022 Office: 770 499 8821 x 338 | Mobile: 678-365-6900 | K45: Waiting for more information
A46: =IF(B46="","","IT-"&Setup!$F$2&TEXT(ROW()-1,"0000")) | B46: Service Ticket #4790246 | NEW RDS | Spreadsheet server | C46: In Progress | D46: Medium | E46: Server Issues | F46: @VC3 | G46: Monica Lopez | H46: 46027.361 | I46: =IF(OR(H46="",B46=""),"",IF(OR(C46="Closed",C46="Resolved"),"-",Setup!$G$2-H46)) | J46: Good morning, This issue was resolved. TX and GA are now using the new RDS icon. But we need the spreadsheet server issue resolved (see attached email). @Johnny Olesh do you have any update on that? Thank you.
A47: =IF(B47="","","IT-"&Setup!$F$2&TEXT(ROW()-1,"0000")) | B47: Computer Locked | ca-toolroom-kiosk2023.main.wallnerexpacinc | User: epicortoolroom1 | C47: Resolved | D47: Low | E47: System Access | F47: @Angel Pinzon @VC3 | G47: Monica Lopez | H47: 46027.453 | I47: =IF(OR(H47="",B47=""),"",IF(OR(C47="Closed",C47="Resolved"),"-",Setup!$G$2-H47)) | J47: Good Morning, Can we get some help to unlock ca-toolroom-kiosk2023 for the "epicortoolroom1" user? The computer got blocked by trying to put the wrong password multiple times and need assistance now. Please confirm that they are able to access the account. Contact Information: Santos Leon mobile: (909) - 908 - 5141
A48: =IF(B48="","","IT-"&Setup!$F$2&TEXT(ROW()-1,"0000")) | B48: Ticket#4795810/WallnerExpac/Fw: ATTENTION | C48: Closed | D48: Low | E48: Spam Removal | F48: @Angel Pinzon @VC3 | G48: Wilhemina Pierce | H48: 46027.58 | I48: =IF(OR(H48="",B48=""),"",IF(OR(C48="Closed",C48="Resolved"),"-",Setup!$G$2-H48)) | J48: Good Afternoon, Can we please get this address blocked? Thanks. Best Regards, | K48: --REPLY above this line to respond-- This ticket has been updated by AJ Stankiewicz AJ Stankiewicz 1/5/2026 4:11 PM Hello Angel, Thank you for reaching out to VC3! I have gone ahead and added the sender to the blocklist. Please feel free to reach back out if you have any other concerns, Have a great day! AJ Stankiewicz Service Technician I _________________________________________________________ Issue / request: Spam email Actions performed: reviewed ticket signed into spam filter ran log trace reviewed email added sender to blocklist Summary: Fw: ATTENTION Status: >Closed Ticket # 4795810 Company: Wallner Expac Contact: Angel Pinzon Phone: (909) 227-3005 Address: 1274 Slater Circle Ontario, CA 91761 Discussion AJ Stankiewicz 1/5/2026 4:11 PM-4:45 PM Hello Angel, Thank you for reaching out to VC3! I have gone ahead and added the sender to the blocklist. Please feel free to reach back out if you have any other concerns, Have a great day!
A49: =IF(B49="","","IT-"&Setup!$F$2&TEXT(ROW()-1,"0000")) | B49: Ticket#4802285/WallnerExpac/block email | C49: Closed | D49: Low | E49: Spam Removal | F49: @Angel Pinzon @VC3 | G49: Angel Pinzon | H49: 46029.332 | I49: =IF(OR(H49="",B49=""),"",IF(OR(C49="Closed",C49="Resolved"),"-",Setup!$G$2-H49)) | J49: Good Morning, Please block spam, multiple users received it. Thanks. Best Regards,
A50: =IF(B50="","","IT-"&Setup!$F$2&TEXT(ROW()-1,"0000")) | B50: New reasons prevent pages in a sitemap from being indexed on site expac.com | C50: Closed | D50: Low | E50: Company Website Issues | F50: @Angel Pinzon | G50: Manuel Menhanca | H50: 46029.342 | I50: =IF(OR(H50="",B50=""),"",IF(OR(C50="Closed",C50="Resolved"),"-",Setup!$G$2-H50)) | J50: Good morning, Angel and Happy New Year. I received the below email from our Google Search Console stating that some pages aren’t being indexed. When you have a moment, can you please look into this? Let me know how I can help, and if you can show me how to fix this, that would be great. I want to learn! 😊 Thanks for your help! | K50: Hi Manny, I updated the .htaccess file on the expac.com server today to fix a Google indexing problem. Google was seeing our website as four different sites (http://expac.com, https://expac.com, http://www.expac.com, and https://www.expac.com) instead of one. This was confusing Google and causing 41 pages to show errors in Search Console. The fix I added tells all visitors and search engines to always go to https://expac.com (no "www"). Now instead of Google crawling four versions of every page, it will only see one, which helps our SEO. You don't need to do anything differently when making updates to the site. Everything will work exactly the same - this was just a behind-the-scenes server configuration change. Let me know if you have any questions. Best Regards,
A51: =IF(B51="","","IT-"&Setup!$F$2&TEXT(ROW()-1,"0000")) | I51: =IF(OR(H51="",B51=""),"",IF(OR(C51="Closed",C51="Resolved"),"-",Setup!$G$2-H51))
A52: =IF(B52="","","IT-"&Setup!$F$2&TEXT(ROW()-1,"0000")) | I52: =IF(OR(H52="",B52=""),"",IF(OR(C52="Closed",C52="Resolved"),"-",Setup!$G$2-H52))
A53: =IF(B53="","","IT-"&Setup!$F$2&TEXT(ROW()-1,"0000")) | I53: =IF(OR(H53="",B53=""),"",IF(OR(C53="Closed",C53="Resolved"),"-",Setup!$G$2-H53))
A54: =IF(B54="","","IT-"&Setup!$F$2&TEXT(ROW()-1,"0000")) | I54: =IF(OR(H54="",B54=""),"",IF(OR(C54="Closed",C54="Resolved"),"-",Setup!$G$2-H54))
...

Sheet Charts
B2: IT SERVICE TICKETS - VISUAL ANALYTICS
B4: * All charts update automatically when new tickets are added to the IT Service Tickets sheet
B5: STATUS DISTRIBUTION | F5: PRIORITY DISTRIBUTION | J5: REQUEST TYPE BREAKDOWN
B6: Status | C6: Count | F6: Priority | G6: Count | J6: Request Type | K6: Total | L6: Open
B7: Closed | C7: =COUNTIF('IT Service Tickets'!C:C,"Closed") | F7: Critical | G7: =COUNTIF('IT Service Tickets'!D:D,"Critical") | J7: Software Issues | K7: =COUNTIF('IT Service Tickets'!E:E,"Software Issues") | L7: =COUNTIFS('IT Service Tickets'!E:E,"Software Issues",'IT Service Tickets'!C:C,"<>Closed",'IT Service Tickets'!C:C,"<>Resolved")
B8: Resolved | C8: =COUNTIF('IT Service Tickets'!C:C,"Resolved") | F8: High | G8: =COUNTIF('IT Service Tickets'!D:D,"High") | J8: Network Problems | K8: =COUNTIF('IT Service Tickets'!E:E,"Network Problems") | L8: =COUNTIFS('IT Service Tickets'!E:E,"Network Problems",'IT Service Tickets'!C:C,"<>Closed",'IT Service Tickets'!C:C,"<>Resolved")
B9: In Progress | C9: =COUNTIF('IT Service Tickets'!C:C,"In Progress") | F9: Medium | G9: =COUNTIF('IT Service Tickets'!D:D,"Medium") | J9: Hardware Setup | K9: =COUNTIF('IT Service Tickets'!E:E,"Hardware Setup") | L9: =COUNTIFS('IT Service Tickets'!E:E,"Hardware Setup",'IT Service Tickets'!C:C,"<>Closed",'IT Service Tickets'!C:C,"<>Resolved")
B10: Waiting for Info | C10: =COUNTIF('IT Service Tickets'!C:C,"Waiting for Info") | F10: Low | G10: =COUNTIF('IT Service Tickets'!D:D,"Low") | J10: Permission Changes | K10: =COUNTIF('IT Service Tickets'!E:E,"Permission Changes") | L10: =COUNTIFS('IT Service Tickets'!E:E,"Permission Changes",'IT Service Tickets'!C:C,"<>Closed",'IT Service Tickets'!C:C,"<>Resolved")
J11: Server Issues | K11: =COUNTIF('IT Service Tickets'!E:E,"Server Issues") | L11: =COUNTIFS('IT Service Tickets'!E:E,"Server Issues",'IT Service Tickets'!C:C,"<>Closed",'IT Service Tickets'!C:C,"<>Resolved")
J12: Software Setup | K12: =COUNTIF('IT Service Tickets'!E:E,"Software Setup") | L12: =COUNTIFS('IT Service Tickets'!E:E,"Software Setup",'IT Service Tickets'!C:C,"<>Closed",'IT Service Tickets'!C:C,"<>Resolved")
J13: Documentation Request | K13: =COUNTIF('IT Service Tickets'!E:E,"Documentation Request") | L13: =COUNTIFS('IT Service Tickets'!E:E,"Documentation Request",'IT Service Tickets'!C:C,"<>Closed",'IT Service Tickets'!C:C,"<>Resolved")
J14: Account Setup | K14: =COUNTIF('IT Service Tickets'!E:E,"Account Setup") | L14: =COUNTIFS('IT Service Tickets'!E:E,"Account Setup",'IT Service Tickets'!C:C,"<>Closed",'IT Service Tickets'!C:C,"<>Resolved")
J15: Hardware Adquisition | K15: =COUNTIF('IT Service Tickets'!E:E,"Hardware Adquisition") | L15: =COUNTIFS('IT Service Tickets'!E:E,"Hardware Adquisition",'IT Service Tickets'!C:C,"<>Closed",'IT Service Tickets'!C:C,"<>Resolved")
J16: Software Acquisition | K16: =COUNTIF('IT Service Tickets'!E:E,"Software Acquisition") | L16: =COUNTIFS('IT Service Tickets'!E:E,"Software Acquisition",'IT Service Tickets'!C:C,"<>Closed",'IT Service Tickets'!C:C,"<>Resolved")
J17: Spam Removal | K17: =COUNTIF('IT Service Tickets'!E:E,"Spam Removal") | L17: =COUNTIFS('IT Service Tickets'!E:E,"Spam Removal",'IT Service Tickets'!C:C,"<>Closed",'IT Service Tickets'!C:C,"<>Resolved")
J18: Email Issues | K18: =COUNTIF('IT Service Tickets'!E:E,"Email Issues") | L18: =COUNTIFS('IT Service Tickets'!E:E,"Email Issues",'IT Service Tickets'!C:C,"<>Closed",'IT Service Tickets'!C:C,"<>Resolved")
J19: Account Changes | K19: =COUNTIF('IT Service Tickets'!E:E,"Account Changes") | L19: =COUNTIFS('IT Service Tickets'!E:E,"Account Changes",'IT Service Tickets'!C:C,"<>Closed",'IT Service Tickets'!C:C,"<>Resolved")
J20: Company Website Issues | K20: =COUNTIF('IT Service Tickets'!E:E,"Company Website Issues") | L20: =COUNTIFS('IT Service Tickets'!E:E,"Company Website Issues",'IT Service Tickets'!C:C,"<>Closed",'IT Service Tickets'!C:C,"<>Resolved")
J21: Feedback Request | K21: =COUNTIF('IT Service Tickets'!E:E,"Feedback Request") | L21: =COUNTIFS('IT Service Tickets'!E:E,"Feedback Request",'IT Service Tickets'!C:C,"<>Closed",'IT Service Tickets'!C:C,"<>Resolved")
J22: System Access | K22: =COUNTIF('IT Service Tickets'!E:E,"System Access") | L22: =COUNTIFS('IT Service Tickets'!E:E,"System Access",'IT Service Tickets'!C:C,"<>Closed",'IT Service Tickets'!C:C,"<>Resolved")
B32: STAFF WORKLOAD | F32: RESOLUTION SUMMARY
B33: Staff | C33: Assigned | D33: Open | F33: Category | G33: Count
B34: Angel Pinzon | C34: =COUNTIF('IT Service Tickets'!F:F,"*Angel Pinzon*") | D34: =COUNTIFS('IT Service Tickets'!F:F,"*Angel Pinzon*",'IT Service Tickets'!C:C,"<>Closed",'IT Service Tickets'!C:C,"<>Resolved") | F34: Open (In Progress + Waiting) | G34: =COUNTIF('IT Service Tickets'!C:C,"In Progress")+COUNTIF('IT Service Tickets'!C:C,"Waiting for Info")
B35: VC3 | C35: =COUNTIF('IT Service Tickets'!F:F,"*VC3*") | D35: =COUNTIFS('IT Service Tickets'!F:F,"*VC3*",'IT Service Tickets'!C:C,"<>Closed",'IT Service Tickets'!C:C,"<>Resolved") | F35: Closed/Resolved | G35: =COUNTIF('IT Service Tickets'!C:C,"Closed")+COUNTIF('IT Service Tickets'!C:C,"Resolved")
B36: Angel + VC3 | C36: =COUNTIF('IT Service Tickets'!F:F,"*@Angel Pinzon @VC3*") | D36: =COUNTIFS('IT Service Tickets'!F:F,"*@Angel Pinzon @VC3*",'IT Service Tickets'!C:C,"<>Closed",'IT Service Tickets'!C:C,"<>Resolved")
B37: Angel + Manuel | C37: =COUNTIF('IT Service Tickets'!F:F,"*@Angel Pinzon @Manuel*") | D37: =COUNTIFS('IT Service Tickets'!F:F,"*@Angel Pinzon @Manuel*",'IT Service Tickets'!C:C,"<>Closed",'IT Service Tickets'!C:C,"<>Resolved")
B58: TICKETS BY WEEK | F58: HIGH PRIORITY OPEN
B59: Week Period | C59: Count | F59: Priority | G59: Open Count
B60: Current Week | C60: =COUNTIFS('IT Service Tickets'!H:H,">="&(Setup!$G$2-WEEKDAY(Setup!$G$2,2)+1),'IT Service Tickets'!H:H,"<="&Setup!$G$2) | F60: Critical Open | G60: =COUNTIFS('IT Service Tickets'!D:D,"Critical",'IT Service Tickets'!C:C,"<>Closed",'IT Service Tickets'!C:C,"<>Resolved")
B61: Last Week | C61: =COUNTIFS('IT Service Tickets'!H:H,">="&(Setup!$G$2-WEEKDAY(Setup!$G$2,2)-6),'IT Service Tickets'!H:H,"<="&(Setup!$G$2-WEEKDAY(Setup!$G$2,2))) | F61: High Open | G61: =COUNTIFS('IT Service Tickets'!D:D,"High",'IT Service Tickets'!C:C,"<>Closed",'IT Service Tickets'!C:C,"<>Resolved")
B62: 2 Weeks Ago | C62: =COUNTIFS('IT Service Tickets'!H:H,">="&(Setup!$G$2-WEEKDAY(Setup!$G$2,2)-13),'IT Service Tickets'!H:H,"<="&(Setup!$G$2-WEEKDAY(Setup!$G$2,2)-7)) | F62: Medium Open | G62: =COUNTIFS('IT Service Tickets'!D:D,"Medium",'IT Service Tickets'!C:C,"<>Closed",'IT Service Tickets'!C:C,"<>Resolved")
B63: 3 Weeks Ago | C63: =COUNTIFS('IT Service Tickets'!H:H,">="&(Setup!$G$2-WEEKDAY(Setup!$G$2,2)-20),'IT Service Tickets'!H:H,"<="&(Setup!$G$2-WEEKDAY(Setup!$G$2,2)-14)) | F63: Low Open | G63: =COUNTIFS('IT Service Tickets'!D:D,"Low",'IT Service Tickets'!C:C,"<>Closed",'IT Service Tickets'!C:C,"<>Resolved")
